<?xml version="1.0"?>
<robot xmlns:xacro="http://www.ros.org/wiki/xacro" name="snake_robot" >

    <xacro:include filename="inertial_macros.xacro"/>
    <xacro:include filename="materials.xacro"/> 
   <!-- <xacro:include filename="ros2_control.xacro"/> -->
   <xacro:include filename="ros2_control.xacro" />
   
   <!-- Constants for robot dimensions -->
    <xacro:property name="PI" value="3.1415926535897931"/>
    
    <odometry_frame>odom</odometry_frame>
    <robot_base_frame>link_1</robot_base_frame>
    <publish_odom>true</publish_odom>
    <publish_odom_tf>true</publish_odom_tf>
    <publish_joint_tf></publish_joint_tf>



    <!--LINK_1 -->
    <link name="link_1">
        <visual>
            <origin xyz="0.0 0.07 0.03" rpy="0.0 0.0 0.0"/>
            <geometry>
                <box size="0.06 0.14 0.06"/>
            </geometry>
            <material name="green"/>
        </visual>
        <collision>
            <origin xyz="0.0 0.07 0.03" rpy="0.0 0.0 0.0"/>
            <geometry>
                <box size="0.06 0.14 0.06"/>
            </geometry>
        </collision>
        <xacro:inertial_box mass="1" x="0.06" y="0.14" z="0.06">
            <origin xyz="0.0 0.07 0.03" rpy="0.0 0.0 0.0"/>
        </xacro:inertial_box>
    </link>

    <!-- JOINT BETWEEN THE TAIL AND THE  LINK_2 -->

    <joint name="link_1_2_joint" type="revolute">
        <parent link="link_1"/>
        <child link="link_2"/>
        <limit lower="-0.785398163397 " upper="0.785398163397" velocity="50.0" effort="1000.0"/>
        <origin xyz="0.0 0.175 0.0" rpy="0 0 0"/>
        <axis xyz="0 0 1"/>
        <joint_properties damping="6.0" friction="6.0"/>
    </joint>
    
    <!-- LINK 2 -->

    <link name="link_2">
        <visual>
            <material name="black"/>
            <origin xyz="0.0 0.07 0.03" rpy="0.0 0.0 0.0"/>
             <geometry>
                <box size="0.06 0.14 0.06"/>
            </geometry>
        </visual>
        <collision>
            <origin xyz="0.0 0.07 0.03" rpy="0.0 0.0 0.0"/>
            <geometry>
                <box size="0.06 0.14 0.06"/>
            </geometry>
        </collision>
        <xacro:inertial_box mass="1" x="0.06" y="0.14" z="0.06">
            <origin xyz="0.0 0.07 0.03" rpy="0.0 0.0 0.0"/>
        </xacro:inertial_box>
    </link>


    
    <!-- JOINT BETWEEM LINK 2 AND 3 -->

    <joint name="link_2_3_joint" type="revolute">
        <parent link="link_2"/>
        <child link="link_3"/>
        <limit lower="-0.785398163397 " upper="0.785398163397" velocity="50.0" effort="1000.0"/>
        <origin xyz="0.0 0.175 0.0" rpy="0 0 0"/>
        <axis xyz="0 0 1"/>
        <joint_properties damping="6.0" friction="6.0"/>
    </joint>
    
    <!-- LINK 3 -->

    <link name="link_3">
        <visual>
            <material name="orange"/>
            <origin xyz="0.0 0.07 0.03" rpy="0.0 0.0 0.0"/>           
            <geometry>
                <box size="0.06 0.14 0.06"/>
            </geometry>
        </visual>
        <collision>
            <origin xyz="0.0 0.07 0.03" rpy="0.0 0.0 0.0"/>
            <geometry>
                <box size="0.06 0.14 0.06"/>
            </geometry>
        </collision>
        <xacro:inertial_box mass="1" x="0.06" y="0.14" z="0.06">
            <origin xyz="0.0 0.07 0.03" rpy="0.0 0.0 0.0"/>
        </xacro:inertial_box>
    </link>   
       


    <!--JOINT BETWEEN LINK 3 AND LINK 4 -->

    <joint name="link_3_4_joint" type="revolute">
        <parent link="link_3"/>
        <child link="link_4"/>
        <limit lower="-0.785398163397 " upper="0.785398163397" velocity="50.0" effort="1000.0"/>
        <origin xyz="0.0 0.175 0.0" rpy="0 0 0"/>
        <axis xyz="0 0 1"/>
        <joint_properties damping="6.0" friction="6.0"/>
    </joint>
    
    <!-- LINK 4 -->

    <link name="link_4">
        <visual>
            <material name="black"/>
            <origin xyz="0.0 0.07 0.03" rpy="0.0 0.0 0.0"/>
            <geometry>
                <box size="0.06 0.14 0.06"/>
            </geometry>
        </visual>
        <collision>
            <origin xyz="0.0 0.07 0.03" rpy="0.0 0.0 0.0"/>
            <geometry>
                <box size="0.06 0.14 0.06"/>
            </geometry>
        </collision>
        <xacro:inertial_box mass="1" x="0.06" y="0.14" z="0.06">
            <origin xyz="0.0 0.07 0.03" rpy="0.0 0.0 0.0"/>
        </xacro:inertial_box>
    </link>
       

   

    <joint name="link_4_5_joint" type="revolute">
        <parent link="link_4"/>
        <child link="link_5"/>
        <limit lower="-0.785398163397 " upper="0.785398163397" velocity="50.0" effort="1000.0"/>
        <origin xyz="0.0 0.175 0.0" rpy="0 0 0"/>
        <axis xyz="0 0 1"/>
        <joint_properties damping="6.0" friction="6.0"/>
    </joint>
    
    <!-- LINK 5-->

    <link name="link_5">
        <visual>
            <material name="orange"/>
            <origin xyz="0.0 0.07 0.03" rpy="0.0 0.0 0.0"/>  
            <geometry>
                <box size="0.06 0.14 0.06"/>
            </geometry>
        </visual>
        <collision>
            <origin xyz="0.0 0.07 0.03" rpy="0.0 0.0 0.0"/>
            <geometry>
                <box size="0.06 0.14 0.06"/>
            </geometry>
        </collision>
        <xacro:inertial_box mass="1" x="0.06" y="0.14" z="0.06">
            <origin xyz="0.0 0.07 0.03" rpy="0.0 0.0 0.0"/>
        </xacro:inertial_box>
    </link>



    <joint name="link_5_6_joint" type="revolute">
        <parent link="link_5"/>
        <child link="link_6"/>
        <limit lower="-0.785398163397 " upper="0.785398163397" velocity="50.0" effort="1000.0"/>
        <origin xyz="0.0 0.175 0.0" rpy="0 0 0"/>
        <axis xyz="0 0 1"/>
        <joint_properties damping="6.0" friction="6.0"/>
    </joint>
    
    <!--  LINK 6-->

    <link name="link_6">
        <visual>
            <material name="black"/>
            <origin xyz="0.0 0.07 0.03" rpy="0.0 0.0 0.0"/>  
            <geometry>
                <box size="0.06 0.14 0.06"/>
            </geometry>
        </visual>
        <collision>
            <origin xyz="0.0 0.07 0.03" rpy="0.0 0.0 0.0"/>
            <geometry>
                <box size="0.06 0.14 0.06"/>
            </geometry>
        </collision>
        <xacro:inertial_box mass="1" x="0.06" y="0.14" z="0.06">
            <origin xyz="0.0 0.07 0.03" rpy="0.0 0.0 0.0"/>
        </xacro:inertial_box>
    </link>

    <!-- JOINT BETWEEN LINK 6 AND LINK 7 -->

    <joint name="link_6_7_joint" type="revolute">
        <parent link="link_6"/>
        <child link="link_7"/>
        <limit lower="-0.785398163397 " upper="0.785398163397" velocity="50.0" effort="1000.0"/>
        <origin xyz="0.0 0.175 0.0" rpy="0 0 0"/>
        <axis xyz="0 0 1"/>
        <joint_properties damping="6.0" friction="6.0"/>
    </joint>
    
    <!--  LINK 7-->

    <link name="link_7">
        <visual>
            <material name="orange"/>
            <origin xyz="0.0 0.07 0.03" rpy="0.0 0.0 0.0"/>  
            <geometry>
                <box size="0.06 0.14 0.06"/>
            </geometry>
        </visual>
        <collision>
            <origin xyz="0.0 0.07 0.03" rpy="0.0 0.0 0.0"/>
            <geometry>
                <box size="0.06 0.14 0.06"/>
            </geometry>
        </collision>
        <xacro:inertial_box mass="1" x="0.06" y="0.14" z="0.06">
            <origin xyz="0.0 0.07 0.03" rpy="0.0 0.0 0.0"/>
        </xacro:inertial_box>
    </link>


    <!-- JOINT BETWEEN LINK 7 AND LINK 8 -->

    <joint name="link_7_8_joint" type="revolute">
        <parent link="link_7"/>
        <child link="link_8"/>
        <limit lower="-0.785398163397 " upper="0.785398163397" velocity="50.0" effort="1000.0"/>
        <origin xyz="0.0 0.175 0.0" rpy="0 0 0"/>
        <axis xyz="0 0 1"/>
        <joint_properties damping="6.0" friction="6.0"/>
    </joint>
    
    <!--  LINK 8-->

    <link name="link_8">
        <visual>
            <material name="black"/>
            <origin xyz="0.0 0.07 0.03" rpy="0.0 0.0 0.0"/>  
            <geometry>
                <box size="0.06 0.14 0.06"/>
            </geometry>
        </visual>
        <collision>
            <origin xyz="0.0 0.07 0.03" rpy="0.0 0.0 0.0"/>
            <geometry>
                <box size="0.06 0.14 0.06"/>
            </geometry>
        </collision>
        <xacro:inertial_box mass="1" x="0.06" y="0.14" z="0.06">
            <origin xyz="0.0 0.07 0.03" rpy="0.0 0.0 0.0"/>
        </xacro:inertial_box>
    </link>


    <!-- JOINT BETWEEN LINK 8 AND LINK 9 -->

    <joint name="link_8_9_joint" type="revolute">
        <parent link="link_8"/>
        <child link="link_9"/>
        <limit lower="-0.785398163397 " upper="0.785398163397" velocity="50.0" effort="1000.0"/>
        <origin xyz="0.0 0.175 0.0" rpy="0 0 0"/>
        <axis xyz="0 0 1"/>
        <joint_properties damping="6.0" friction="6.0"/>
    </joint>
    
    <!--  LINK 9-->

    <link name="link_9">
        <visual>
            <material name="orange"/>
            <origin xyz="0.0 0.07 0.03" rpy="0.0 0.0 0.0"/>  
            <geometry>
                <box size="0.06 0.14 0.06"/>
            </geometry>
        </visual>
        <collision>
            <origin xyz="0.0 0.07 0.03" rpy="0.0 0.0 0.0"/>
            <geometry>
                <box size="0.06 0.14 0.06"/>
            </geometry>
        </collision>
        <xacro:inertial_box mass="1" x="0.06" y="0.14" z="0.06">
            <origin xyz="0.0 0.07 0.03" rpy="0.0 0.0 0.0"/>
        </xacro:inertial_box>
    </link>

    <!-- JOINT BETWEEN LINK 9 AND LINK 10 -->

    <joint name="link_9_10_joint" type="revolute">
        <parent link="link_9"/>
        <child link="link_10"/>
        <limit lower="-0.785398163397 " upper="0.785398163397" velocity="50.0" effort="1000.0"/>
        <origin xyz="0.0 0.175 0.0" rpy="0 0 0"/>
        <axis xyz="0 0 1"/>
        <joint_properties damping="6.0" friction="6.0"/>
    </joint>
    
    <!--  LINK 10-->

    <link name="link_10">
        <visual>
            <material name="black"/>
            <origin xyz="0.0 0.07 0.03" rpy="0.0 0.0 0.0"/>  
            <geometry>
                <box size="0.06 0.14 0.06"/>
            </geometry>
        </visual>
        <collision>
            <origin xyz="0.0 0.07 0.03" rpy="0.0 0.0 0.0"/>
            <geometry>
                <box size="0.06 0.14 0.06"/>
            </geometry>
        </collision>
        <xacro:inertial_box mass="1" x="0.06" y="0.14" z="0.06">
            <origin xyz="0.0 0.07 0.03" rpy="0.0 0.0 0.0"/>
        </xacro:inertial_box>
        
    </link>
    
    <!--gazebo>
          <plugin name="gazebo_ros_joint_state_publisher"
                    filename="libgazebo_ros_joint_state_publisher.so">
                    <update_rate>50</update_rate>
                    <joint_name>link_1_2_joint</joint_name>
                    <joint_name>link_2_3_joint</joint_name>
                    <joint_name>link_3_4_joint</joint_name>
                    <joint_name>link_4_5_joint</joint_name>
                    <joint_name>link_5_6_joint</joint_name>
                    <joint_name>link_6_7_joint</joint_name>
                    <joint_name>link_7_8_joint</joint_name>
                    <joint_name>link_8_9_joint</joint_name>
                    <joint_name>link_9_10_joint</joint_name>
        </plugin>
    </gazebo-->
</robot>
